Workbook

Sheet Rules
A1: 天赋设计 V2 · 规则
A2: 这张表是系统规则的权威说明；Tree_View 只负责展示，Basic/Advanced 数据表才用于实现。
A4: 文档定位
A5: 规则项 | B5: 定义/公式 | C5: 设计意图 | D5: 实现约束
A6: Basic | B6: 本轮成长 | C6: 使用金币购买；升华时重置。 | D6: 改变本轮操作、收益、矿池与地块构筑。
A7: Advanced | B7: 永久成长 | C7: 使用升华点购买；永久保留。 | D7: 优先提供自动化、离线、保留槽与新规则。
A8: 重置·升华 | B8: 中心操作 | C8: 不是价格为0的普通天赋。 | D8: 显示本次可得点数、下一点门槛和重置清单。
A10: 叠加顺序
A11: 规则项 | B11: 定义/公式 | C11: 设计意图 | D11: 实现约束
A12: 通用公式 | B12: 最终值 = (基础值 + 固定加成) × (1 + 同类百分比之和) × 矿物层 × 地块层 × Prestige层 × 临时Buff层 | C12: 同一类先相加，不同系统才相乘。 | D12: 普通天赋避免新增独立乘区。
A13: 里程碑倍率 | B13: ×2只用于分支终点、稀有事件或明确里程碑。 | C13: 永久普通节点单独不应跨越多个内容阶段。 | D13: 临时Buff可以强，但要限制持续时间和组合。
A14: 速度 | B14: 所有周期效率写成 rate bonus。 | C14: effective_interval = base_interval / (1 + rate_bonus) | D14: 有效间隔下限建议0.25秒。
A15: 上限 | B15: 暴击率≤50%；连击金币≤100%；单条协同≤3倍；water返还≤20%。 | C15: 上限写进数据表，不靠描述约定。 | D15: 同一效果的多个入口必须共享上限。
A17: 成本与回本
A18: 规则项 | B18: 定义/公式 | C18: 设计意图 | D18: 实现约束
A19: 天赋等级 | B19: rank_cost = round(base_cost × growth^(rank-1)) | C19: 普通可升级天赋默认 growth=4~5。 | D19: 关键节点使用人工成本，不按树圈数×1000。
A20: 重复放置 | B20: place_cost = ceil(place_base_cost × 1.15^owned) | C20: 只用于实际拥有的重复地块/设施。 | D20: 出售返还建议25%，避免买卖套利。
A21: 定价依据 | B21: payback_seconds = cost / estimated_delta_cps | C21: 早期目标60~90秒；中期约300秒；里程碑约600秒。 | D21: 解锁/玩法节点允许无直接回本，但要标注内容价值。
A23: 升华
A24: 规则项 | B24: 定义/公式 | C24: 设计意图 | D24: 实现约束
A25: 门槛 | B25: C = 第一次升华要求的终身金币；本版默认1,000,000。 | C25: 若目标首轮仅30~60分钟，可把C降到100,000。 | D25: 必须用实机产出回放校准。
A26: 总点数 | B26: L<C时为0；否则 floor(10 × (L/C)^(1/3))。 | C26: 1C=10点，8C=20点，27C=30点。 | D26: 实现时先转float，并在floor前做9位小数round，避免125C算成49点。
A27: 永久倍率 | B27: prestige_multiplier = 1 + 历史总升华点 × 1% + Advanced同层加成 | C27: 消费点数不降低永久倍率。 | D27: 分别保存 total_earned 与 unspent。
A28: 重置范围 | B28: 清空金币、Basic等级、当前棋盘、临时Buff与本轮统计。 | C28: 保留终身金币、历史升华点、Advanced和永久槽。 | D28: 已失去解锁资格的地块不能残留在棋盘。
A30: V2初始内容
A31: 规则项 | B31: 定义/公式 | C31: 设计意图 | D31: 实现约束
A32: 矿物 | B32: 初始：coal / iron / zinc。 | C32: 其余通过矿石分支解锁。 | D32: 当前代码实际会加载全部矿物，实施时需增加过滤。
A33: 矿值阶梯 | B33: V2建议：gold 12 / crystal 200 / obsidian 1.2K / diamond 5K / cat 200K。 | C33: 在保持现有权重与解锁价格时，各档真实回本约7~10分钟。 | D33: Content_Catalog同时保留当前值和V2建议值；代码尚未修改。
A34: 地块 | B34: 初始：dirt / grass。 | C34: stone及以后通过地块分支解锁。 | D34: 当前抽屉实际显示全部地块且免费放置。
A35: 矿物等级 | B35: Lv1普通；Lv2高级；Lv3巨大。 | C35: 价值倍率1/2/4；HP倍率1/1.5/2.25。 | D35: upgrade不可绕过等级解锁上限。
A37: 实现契约
A38: 规则项 | B38: 定义/公式 | C38: 设计意图 | D38: 实现约束
A39: 权威经济 | B39: GameManager/PlayerProgression只保留一套金币与购买等级。 | C39: 购买必须原子扣款并立即保存。 | D39: TalentGrid不再维护starting_gold演示钱包。
A40: 奖励上下文 | B40: 奖励事件携带cause：manual / auto_pick / fire / volcano / water。 | C40: 手挖专属、连击和纪录才可正确判断。 | D40: 同一个入口计算全部倍率，避免重复乘算。
A41: 数据定义 | B41: TalentDef需要多个前置、等级、效果数组、上限和互斥组。 | C41: 缺失前置ID必须报错，不能当作无前置。 | D41: 运行时通过ModifierSet查询，不改共享.tres资源。
A42: 数值范围 | B42: 当前金币为Godot int64。 | C42: 常规流程建议控制在10^15左右。 | D42: 若要超过Qi量级，先实现BigNumber。
A44: 与旧版相比
A45: • 保留四方向布局；移除‘每圈×1000’作为统一成本规则。
A46: • 删除不存在的 emerald；rock 改为 stone；volcano 改为 volcano_stable。
A47: • grass/dirt 改为初始地块，不再作为解锁节点。
...

Sheet Basic_Talents
A1: Basic Talents · 本轮天赋
A2: 一行一个节点；成本公式、回本估算和实现依赖均可筛选。黄色输入列可调整，蓝色列为公式。
A4: Node_ID | B4: 名称 | C4: 分支 | D4: 层级 | E4: X | F4: Y | G4: 前置_IDs | H4: 最大等级 | I4: 货币 | J4: 基础成本 | K4: 等级成本倍率 | L4: Rank1成本 | M4: Rank2成本 | N4: Rank3成本 | O4: 解锁条件 | P4: Effect_Type | Q4: Target_Kind | R4: Target_ID | S4: Operation | T4: 每级数值 | U4: 上限 | V4: 重置行为 | W4: 玩家描述 | X4: 估算ΔCPS | Y4: Rank1回本秒 | Z4: 目标回本秒 | AA4: 建议基础成本 | AB4: 实现说明
A5: pickaxe_tempered | B5: 淬火镐头 | C5: 镐子 | D5: 1 | E5: 0 | F5: -1 | H5: 3 | I5: 金币 | J5: 50 | K5: 4 | L5: =J5 | M5: =IF(H5>=2,ROUND(J5*K5,0),"") | N5: =IF(H5>=3,ROUND(J5*K5^2,0),"") | O5: 无 | P5: PICK_DAMAGE_FLAT | Q5: PICKAXE | R5: manual_pickaxe | S5: ADD | T5: 5 | U5: 15 | V5: 升华时重置 | W5: 每级使手动镐子伤害 +5。 | X5: =IF(P5="COIN_BONUS",INDEX(Balance!$E$4:$E$9,MIN(6,D5))*T5,IF(P5="MANUAL_REWARD_BONUS",INDEX(Balance!$E$4:$E$9,MIN(6,D5))*Balance!$B$9*T5,IF(P5="GLOBAL_MULTIPLIER",INDEX(Balance!$E$4:$E$9,MIN(6,D5))*(T5-1),""))) | Y5: =IFERROR(L5/X5,"") | Z5: =IF(D5<=2,Balance!$B$10,IF(D5<=4,Balance!$B$11,Balance!$B$12)) | AA5: =IF(X5="","",ROUND(X5*Z5,0)) | AB5: 接入 GameManager._mine_at；伤害收益需战斗模拟。
A6: pickaxe_sharp | B6: 锐利镐刃 | C6: 镐子 | D6: 2 | E6: 0 | F6: -2 | G6: pickaxe_tempered | H6: 3 | I6: 金币 | J6: 250 | K6: 4 | L6: =J6 | M6: =IF(H6>=2,ROUND(J6*K6,0),"") | N6: =IF(H6>=3,ROUND(J6*K6^2,0),"") | O6: 淬火镐头至少1级 | P6: PICK_DAMAGE_BONUS | Q6: PICKAXE | R6: manual_pickaxe | S6: ADD_PERCENT | T6: 0.25 | U6: 0.75 | V6: 升华时重置 | W6: 每级使手动镐子伤害 +25%。 | X6: =IF(P6="COIN_BONUS",INDEX(Balance!$E$4:$E$9,MIN(6,D6))*T6,IF(P6="MANUAL_REWARD_BONUS",INDEX(Balance!$E$4:$E$9,MIN(6,D6))*Balance!$B$9*T6,IF(P6="GLOBAL_MULTIPLIER",INDEX(Balance!$E$4:$E$9,MIN(6,D6))*(T6-1),""))) | Y6: =IFERROR(L6/X6,"") | Z6: =IF(D6<=2,Balance!$B$10,IF(D6<=4,Balance!$B$11,Balance!$B$12)) | AA6: =IF(X6="","",ROUND(X6*Z6,0)) | AB6: 同类伤害百分比先相加。
A7: pickaxe_crit | B7: 幸运重击 | C7: 镐子 | D7: 3 | E7: 0 | F7: -3 | G7: pickaxe_sharp | H7: 2 | I7: 金币 | J7: 1000 | K7: 5 | L7: =J7 | M7: =IF(H7>=2,ROUND(J7*K7,0),"") | N7: =IF(H7>=3,ROUND(J7*K7^2,0),"") | O7: 锐利镐刃至少1级 | P7: CRIT_CHANCE | Q7: PICKAXE | R7: manual_pickaxe | S7: ADD_PERCENT | T7: 0.1 | U7: 0.2 | V7: 升华时重置 | W7: 每级获得 10% 暴击率；暴击基础造成 2 倍伤害。 | X7: =IF(P7="COIN_BONUS",INDEX(Balance!$E$4:$E$9,MIN(6,D7))*T7,IF(P7="MANUAL_REWARD_BONUS",INDEX(Balance!$E$4:$E$9,MIN(6,D7))*Balance!$B$9*T7,IF(P7="GLOBAL_MULTIPLIER",INDEX(Balance!$E$4:$E$9,MIN(6,D7))*(T7-1),""))) | Y7: =IFERROR(L7/X7,"") | Z7: =IF(D7<=2,Balance!$B$10,IF(D7<=4,Balance!$B$11,Balance!$B$12)) | AA7: =IF(X7="","",ROUND(X7*Z7,0)) | AB7: 需新增暴击结算；总暴击率建议上限50%。
A8: pickaxe_crit_power | B8: 精准爆破 | C8: 镐子 | D8: 4 | E8: -1 | F8: -4 | G8: pickaxe_crit | H8: 2 | I8: 金币 | J8: 5000 | K8: 5 | L8: =J8 | M8: =IF(H8>=2,ROUND(J8*K8,0),"") | N8: =IF(H8>=3,ROUND(J8*K8^2,0),"") | O8: 幸运重击至少1级 | P8: CRIT_MULTIPLIER | Q8: PICKAXE | R8: manual_pickaxe | S8: ADD | T8: 0.5 | U8: 3 | V8: 升华时重置 | W8: 每级使暴击倍率 +0.5。 | X8: =IF(P8="COIN_BONUS",INDEX(Balance!$E$4:$E$9,MIN(6,D8))*T8,IF(P8="MANUAL_REWARD_BONUS",INDEX(Balance!$E$4:$E$9,MIN(6,D8))*Balance!$B$9*T8,IF(P8="GLOBAL_MULTIPLIER",INDEX(Balance!$E$4:$E$9,MIN(6,D8))*(T8-1),""))) | Y8: =IFERROR(L8/X8,"") | Z8: =IF(D8<=2,Balance!$B$10,IF(D8<=4,Balance!$B$11,Balance!$B$12)) | AA8: =IF(X8="","",ROUND(X8*Z8,0)) | AB8: 基础暴击倍率2.0；最终建议不超过3.0。
A9: pickaxe_double | B9: 双重敲击 | C9: 镐子 | D9: 4 | E9: 1 | F9: -4 | G9: pickaxe_crit | H9: 1 | I9: 金币 | J9: 8000 | K9: 1 | L9: =J9 | M9: =IF(H9>=2,ROUND(J9*K9,0),"") | N9: =IF(H9>=3,ROUND(J9*K9^2,0),"") | O9: 幸运重击至少1级 | P9: EXTRA_HIT_CHANCE | Q9: PICKAXE | R9: manual_pickaxe | S9: ADD_PERCENT | T9: 0.08 | U9: 0.25 | V9: 升华时重置 | W9: 手动攻击有 8% 概率追加一次完整攻击。 | X9: =IF(P9="COIN_BONUS",INDEX(Balance!$E$4:$E$9,MIN(6,D9))*T9,IF(P9="MANUAL_REWARD_BONUS",INDEX(Balance!$E$4:$E$9,MIN(6,D9))*Balance!$B$9*T9,IF(P9="GLOBAL_MULTIPLIER",INDEX(Balance!$E$4:$E$9,MIN(6,D9))*(T9-1),""))) | Y9: =IFERROR(L9/X9,"") | Z9: =IF(D9<=2,Balance!$B$10,IF(D9<=4,Balance!$B$11,Balance!$B$12)) | AA9: =IF(X9="","",ROUND(X9*Z9,0)) | AB9: 需防止追加攻击再次触发自身。
A10: pickaxe_overkill | B10: 余震 | C10: 镐子 | D10: 5 | E10: -1 | F10: -5 | G10: pickaxe_crit_power | H10: 1 | I10: 金币 | J10: 25000 | K10: 1 | L10: =J10 | M10: =IF(H10>=2,ROUND(J10*K10,0),"") | N10: =IF(H10>=3,ROUND(J10*K10^2,0),"") | O10: 精准爆破至少1级 | P10: OVERKILL_SPLASH | Q10: PICKAXE | R10: orthogonal_ore | S10: SET | T10: 0.5 | U10: 0.5 | V10: 升华时重置 | W10: 击破矿物时，50% 溢出伤害传给一个相邻矿物。 | X10: =IF(P10="COIN_BONUS",INDEX(Balance!$E$4:$E$9,MIN(6,D10))*T10,IF(P10="MANUAL_REWARD_BONUS",INDEX(Balance!$E$4:$E$9,MIN(6,D10))*Balance!$B$9*T10,IF(P10="GLOBAL_MULTIPLIER",INDEX(Balance!$E$4:$E$9,MIN(6,D10))*(T10-1),""))) | Y10: =IFERROR(L10/X10,"") | Z10: =IF(D10<=2,Balance!$B$10,IF(D10<=4,Balance!$B$11,Balance!$B$12)) | AA10: =IF(X10="","",ROUND(X10*Z10,0)) | AB10: 需要击杀来源与溢出伤害上下文。
A11: pickaxe_shockwave | B11: 冲击波 | C11: 镐子 | D11: 5 | E11: 1 | F11: -5 | G11: pickaxe_double | H11: 1 | I11: 金币 | J11: 150000 | K11: 1 | L11: =J11 | M11: =IF(H11>=2,ROUND(J11*K11,0),"") | N11: =IF(H11>=3,ROUND(J11*K11^2,0),"") | O11: 双重敲击 | P11: PICK_AOE | Q11: PICKAXE | R11: orthogonal_ore | S11: SET | T11: 0.4 | U11: 0.4 | V11: 升华时重置 | W11: 手动攻击时，相邻矿物承受本次伤害的 40%。 | X11: =IF(P11="COIN_BONUS",INDEX(Balance!$E$4:$E$9,MIN(6,D11))*T11,IF(P11="MANUAL_REWARD_BONUS",INDEX(Balance!$E$4:$E$9,MIN(6,D11))*Balance!$B$9*T11,IF(P11="GLOBAL_MULTIPLIER",INDEX(Balance!$E$4:$E$9,MIN(6,D11))*(T11-1),""))) | Y11: =IFERROR(L11/X11,"") | Z11: =IF(D11<=2,Balance!$B$10,IF(D11<=4,Balance!$B$11,Balance!$B$12)) | AA11: =IF(X11="","",ROUND(X11*Z11,0)) | AB11: 需要 AoE 管线；避免与双击递归触发。
A12: coin_appraisal | B12: 矿物鉴价 | C12: 金币 | D12: 1 | E12: -1 | F12: 0 | H12: 3 | I12: 金币 | J12: 10 | K12: 5 | L12: =J12 | M12: =IF(H12>=2,ROUND(J12*K12,0),"") | N12: =IF(H12>=3,ROUND(J12*K12^2,0),"") | O12: 无 | P12: COIN_BONUS | Q12: GLOBAL | R12: all_rewards | S12: ADD_PERCENT | T12: 0.1 | U12: 0.3 | V12: 升华时重置 | W12: 每级使全部金币收益 +10%。 | X12: =IF(P12="COIN_BONUS",INDEX(Balance!$E$4:$E$9,MIN(6,D12))*T12,IF(P12="MANUAL_REWARD_BONUS",INDEX(Balance!$E$4:$E$9,MIN(6,D12))*Balance!$B$9*T12,IF(P12="GLOBAL_MULTIPLIER",INDEX(Balance!$E$4:$E$9,MIN(6,D12))*(T12-1),""))) | Y12: =IFERROR(L12/X12,"") | Z12: =IF(D12<=2,Balance!$B$10,IF(D12<=4,Balance!$B$11,Balance!$B$12)) | AA12: =IF(X12="","",ROUND(X12*Z12,0)) | AB12: Rank成本10/50/250；按真实增量收益定价，而非攒够时间。
A13: coin_handmade | B13: 手工精品 | C13: 金币 | D13: 2 | E13: -2 | F13: 0 | G13: coin_appraisal | H13: 2 | I13: 金币 | J13: 25 | K13: 5 | L13: =J13 | M13: =IF(H13>=2,ROUND(J13*K13,0),"") | N13: =IF(H13>=3,ROUND(J13*K13^2,0),"") | O13: 矿物鉴价至少1级 | P13: MANUAL_REWARD_BONUS | Q13: GLOBAL | R13: manual_kill | S13: ADD_PERCENT | T13: 0.25 | U13: 0.5 | V13: 升华时重置 | W13: 每级使手动击破的矿物收益 +25%。 | X13: =IF(P13="COIN_BONUS",INDEX(Balance!$E$4:$E$9,MIN(6,D13))*T13,IF(P13="MANUAL_REWARD_BONUS",INDEX(Balance!$E$4:$E$9,MIN(6,D13))*Balance!$B$9*T13,IF(P13="GLOBAL_MULTIPLIER",INDEX(Balance!$E$4:$E$9,MIN(6,D13))*(T13-1),""))) | Y13: =IFERROR(L13/X13,"") | Z13: =IF(D13<=2,Balance!$B$10,IF(D13<=4,Balance!$B$11,Balance!$B$12)) | AA13: =IF(X13="","",ROUND(X13*Z13,0)) | AB13: ore_removed 需携带 cause，区分手挖/火焰/火山/水。
A14: coin_streak | B14: 连续开采 | C14: 金币 | D14: 3 | E14: -3 | F14: 0 | G14: coin_handmade | H14: 1 | I14: 金币 | J14: 500 | K14: 1 | L14: =J14 | M14: =IF(H14>=2,ROUND(J14*K14,0),"") | N14: =IF(H14>=3,ROUND(J14*K14^2,0),"") | O14: 手工精品至少1级 | P14: UNLOCK_STREAK | Q14: SYSTEM | R14: mining_streak | S14: UNLOCK | T14: 0.02 | U14: 0.2 | V14: 升华时重置 | W14: 5秒内连续击破，每层金币 +2%，最多10层。 | X14: =IF(P14="COIN_BONUS",INDEX(Balance!$E$4:$E$9,MIN(6,D14))*T14,IF(P14="MANUAL_REWARD_BONUS",INDEX(Balance!$E$4:$E$9,MIN(6,D14))*Balance!$B$9*T14,IF(P14="GLOBAL_MULTIPLIER",INDEX(Balance!$E$4:$E$9,MIN(6,D14))*(T14-1),""))) | Y14: =IFERROR(L14/X14,"") | Z14: =IF(D14<=2,Balance!$B$10,IF(D14<=4,Balance!$B$11,Balance!$B$12)) | AA14: =IF(X14="","",ROUND(X14*Z14,0)) | AB14: 新增 streak 状态；自动击杀是否续连击需明确，V2默认不续。
A15: coin_stone_appraiser | B15: 岩层鉴价师 | C15: 金币 | D15: 4 | E15: -4 | F15: -1 | G15: coin_streak | H15: 1 | I15: 金币 | J15: 5000 | K15: 1 | L15: =J15 | M15: =IF(H15>=2,ROUND(J15*K15,0),"") | N15: =IF(H15>=3,ROUND(J15*K15^2,0),"") | O15: 连续开采 | P15: TILE_VALUE_MULTIPLIER | Q15: TILE | R15: stone | S15: ADD | T15: 0.3 | U15: 1.8 | V15: 升华时重置 | W15: 石头地块的价值倍率从 1.5 提升到 1.8。 | X15: =IF(P15="COIN_BONUS",INDEX(Balance!$E$4:$E$9,MIN(6,D15))*T15,IF(P15="MANUAL_REWARD_BONUS",INDEX(Balance!$E$4:$E$9,MIN(6,D15))*Balance!$B$9*T15,IF(P15="GLOBAL_MULTIPLIER",INDEX(Balance!$E$4:$E$9,MIN(6,D15))*(T15-1),""))) | Y15: =IFERROR(L15/X15,"") | Z15: =IF(D15<=2,Balance!$B$10,IF(D15<=4,Balance!$B$11,Balance!$B$12)) | AA15: =IF(X15="","",ROUND(X15*Z15,0)) | AB15: 通过 ModifierSet 查询，禁止直接修改共享 TileDef。
A16: coin_record_fever | B16: 纪录狂热 | C16: 金币 | D16: 4 | E16: -4 | F16: 1 | G16: coin_streak | H16: 1 | I16: 金币 | J16: 50000 | K16: 1 | L16: =J16 | M16: =IF(H16>=2,ROUND(J16*K16,0),"") | N16: =IF(H16>=3,ROUND(J16*K16^2,0),"") | O16: 连续开采 | P16: UNLOCK_RECORD_BUFF | Q16: SYSTEM | R16: rolling_60s_income | S16: UNLOCK | T16: 2 | U16: 2 | V16: 升华时重置 | W16: 最近60秒收益首次超过历史纪录时，金币收益 ×2，持续10秒。 | X16: =IF(P16="COIN_BONUS",INDEX(Balance!$E$4:$E$9,MIN(6,D16))*T16,IF(P16="MANUAL_REWARD_BONUS",INDEX(Balance!$E$4:$E$9,MIN(6,D16))*Balance!$B$9*T16,IF(P16="GLOBAL_MULTIPLIER",INDEX(Balance!$E$4:$E$9,MIN(6,D16))*(T16-1),""))) | Y16: =IFERROR(L16/X16,"") | Z16: =IF(D16<=2,Balance!$B$10,IF(D16<=4,Balance!$B$11,Balance!$B$12)) | AA16: =IF(X16="","",ROUND(X16*Z16,0)) | AB16: 按不含纪录Buff的基础收益比较；至少60秒冷却，仅跨过旧纪录时触发。
A17: coin_golden_ratio | B17: 黄金比例 | C17: 金币 | D17: 5 | E17: -5 | F17: 0 | G17: coin_stone_appraiser,coin_record_fever | H17: 1 | I17: 金币 | J17: 300000 | K17: 1 | L17: =J17 | M17: =IF(H17>=2,ROUND(J17*K17,0),"") | N17: =IF(H17>=3,ROUND(J17*K17^2,0),"") | O17: 同时购买岩层鉴价师和纪录狂热 | P17: GLOBAL_MULTIPLIER | Q17: GLOBAL | R17: all_rewards | S17: MULTIPLY | T17: 2 | U17: 2 | V17: 升华时重置 | W17: 里程碑：全部金币收益 ×2。 | X17: =IF(P17="COIN_BONUS",INDEX(Balance!$E$4:$E$9,MIN(6,D17))*T17,IF(P17="MANUAL_REWARD_BONUS",INDEX(Balance!$E$4:$E$9,MIN(6,D17))*Balance!$B$9*T17,IF(P17="GLOBAL_MULTIPLIER",INDEX(Balance!$E$4:$E$9,MIN(6,D17))*(T17-1),""))) | Y17: =IFERROR(L17/X17,"") | Z17: =IF(D17<=2,Balance!$B$10,IF(D17<=4,Balance!$B$11,Balance!$B$12)) | AA17: =IF(X17="","",ROUND(X17*Z17,0)) | AB17: 独立乘区只用于分支终点；购买前CPS约500时回本约10分钟。
A18: ore_unlock_gold | B18: 发现黄金 | C18: 矿石 | D18: 1 | E18: 1 | F18: 0 | H18: 1 | I18: 金币 | J18: 250 | K18: 1 | L18: =J18 | M18: =IF(H18>=2,ROUND(J18*K18,0),"") | N18: =IF(H18>=3,ROUND(J18*K18^2,0),"") | O18: 初始仅 coal / iron / zinc | P18: UNLOCK_ORE | Q18: ORE | R18: gold | S18: UNLOCK | T18: 1 | U18: 1 | V18: 升华时重置 | W18: 允许 gold 加入自然生成矿池。 | X18: =IF(P18="COIN_BONUS",INDEX(Balance!$E$4:$E$9,MIN(6,D18))*T18,IF(P18="MANUAL_REWARD_BONUS",INDEX(Balance!$E$4:$E$9,MIN(6,D18))*Balance!$B$9*T18,IF(P18="GLOBAL_MULTIPLIER",INDEX(Balance!$E$4:$E$9,MIN(6,D18))*(T18-1),""))) | Y18: =IFERROR(L18/X18,"") | Z18: =IF(D18<=2,Balance!$B$10,IF(D18<=4,Balance!$B$11,Balance!$B$12)) | AA18: =IF(X18="","",ROUND(X18*Z18,0)) | AB18: 当前代码开局强制生成 gold，实施解锁时必须同步修改。
A19: ore_unlock_crystal | B19: 水晶勘探 | C19: 矿石 | D19: 2 | E19: 2 | F19: 0 | G19: ore_unlock_gold | H19: 1 | I19: 金币 | J19: 2500 | K19: 1 | L19: =J19 | M19: =IF(H19>=2,ROUND(J19*K19,0),"") | N19: =IF(H19>=3,ROUND(J19*K19^2,0),"") | O19: 发现黄金 | P19: UNLOCK_ORE | Q19: ORE | R19: crystal | S19: UNLOCK | T19: 1 | U19: 1 | V19: 升华时重置 | W19: 允许 crystal 加入自然生成矿池。 | X19: =IF(P19="COIN_BONUS",INDEX(Balance!$E$4:$E$9,MIN(6,D19))*T19,IF(P19="MANUAL_REWARD_BONUS",INDEX(Balance!$E$4:$E$9,MIN(6,D19))*Balance!$B$9*T19,IF(P19="GLOBAL_MULTIPLIER",INDEX(Balance!$E$4:$E$9,MIN(6,D19))*(T19-1),""))) | Y19: =IFERROR(L19/X19,"") | Z19: =IF(D19<=2,Balance!$B$10,IF(D19<=4,Balance!$B$11,Balance!$B$12)) | AA19: =IF(X19="","",ROUND(X19*Z19,0)) | AB19: spawn 地块目前固定生成 crystal，必须接受解锁校验。
A20: ore_unlock_obsidian | B20: 黑曜层 | C20: 矿石 | D20: 3 | E20: 3 | F20: 0 | G20: ore_unlock_crystal | H20: 1 | I20: 金币 | J20: 12000 | K20: 1 | L20: =J20 | M20: =IF(H20>=2,ROUND(J20*K20,0),"") | N20: =IF(H20>=3,ROUND(J20*K20^2,0),"") | O20: 水晶勘探 | P20: UNLOCK_ORE | Q20: ORE | R20: obsidian | S20: UNLOCK | T20: 1 | U20: 1 | V20: 升华时重置 | W20: 允许 obsidian 加入自然生成矿池。 | X20: =IF(P20="COIN_BONUS",INDEX(Balance!$E$4:$E$9,MIN(6,D20))*T20,IF(P20="MANUAL_REWARD_BONUS",INDEX(Balance!$E$4:$E$9,MIN(6,D20))*Balance!$B$9*T20,IF(P20="GLOBAL_MULTIPLIER",INDEX(Balance!$E$4:$E$9,MIN(6,D20))*(T20-1),""))) | Y20: =IFERROR(L20/X20,"") | Z20: =IF(D20<=2,Balance!$B$10,IF(D20<=4,Balance!$B$11,Balance!$B$12)) | AA20: =IF(X20="","",ROUND(X20*Z20,0)) | AB20: DefDb.roll_ore 增加解锁过滤。
A21: ore_unlock_diamond | B21: 钻石钻探 | C21: 矿石 | D21: 4 | E21: 4 | F21: 0 | G21: ore_unlock_obsidian | H21: 1 | I21: 金币 | J21: 30000 | K21: 1 | L21: =J21 | M21: =IF(H21>=2,ROUND(J21*K21,0),"") | N21: =IF(H21>=3,ROUND(J21*K21^2,0),"") | O21: 黑曜层 | P21: UNLOCK_ORE | Q21: ORE | R21: diamond | S21: UNLOCK | T21: 1 | U21: 1 | V21: 升华时重置 | W21: 允许 diamond 加入自然生成矿池。 | X21: =IF(P21="COIN_BONUS",INDEX(Balance!$E$4:$E$9,MIN(6,D21))*T21,IF(P21="MANUAL_REWARD_BONUS",INDEX(Balance!$E$4:$E$9,MIN(6,D21))*Balance!$B$9*T21,IF(P21="GLOBAL_MULTIPLIER",INDEX(Balance!$E$4:$E$9,MIN(6,D21))*(T21-1),""))) | Y21: =IFERROR(L21/X21,"") | Z21: =IF(D21<=2,Balance!$B$10,IF(D21<=4,Balance!$B$11,Balance!$B$12)) | AA21: =IF(X21="","",ROUND(X21*Z21,0)) | AB21: DefDb.roll_ore 增加解锁过滤。
A22: ore_unlock_cat | B22: 猫矿传说 | C22: 矿石 | D22: 5 | E22: 5 | F22: 0 | G22: ore_unlock_diamond | H22: 1 | I22: 金币 | J22: 250000 | K22: 1 | L22: =J22 | M22: =IF(H22>=2,ROUND(J22*K22,0),"") | N22: =IF(H22>=3,ROUND(J22*K22^2,0),"") | O22: 钻石钻探 | P22: UNLOCK_ORE | Q22: ORE | R22: cat | S22: UNLOCK | T22: 1 | U22: 1 | V22: 升华时重置 | W22: 允许极稀有的 cat 加入自然生成矿池。 | X22: =IF(P22="COIN_BONUS",INDEX(Balance!$E$4:$E$9,MIN(6,D22))*T22,IF(P22="MANUAL_REWARD_BONUS",INDEX(Balance!$E$4:$E$9,MIN(6,D22))*Balance!$B$9*T22,IF(P22="GLOBAL_MULTIPLIER",INDEX(Balance!$E$4:$E$9,MIN(6,D22))*(T22-1),""))) | Y22: =IFERROR(L22/X22,"") | Z22: =IF(D22<=2,Balance!$B$10,IF(D22<=4,Balance!$B$11,Balance!$B$12)) | AA22: =IF(X22="","",ROUND(X22*Z22,0)) | AB22: 保持低权重；猫矿是内容奖励而非稳定经济来源。
A23: ore_large_vein | B23: 大型矿脉 | C23: 矿石 | D23: 3 | E23: 3 | F23: -1 | G23: ore_unlock_crystal | H23: 1 | I23: 金币 | J23: 5000 | K23: 1 | L23: =J23 | M23: =IF(H23>=2,ROUND(J23*K23,0),"") | N23: =IF(H23>=3,ROUND(J23*K23^2,0),"") | O23: 水晶勘探 | P23: NATURAL_LEVEL_CHANCE | Q23: ORE | R23: level_2 | S23: SET | T23: 0.05 | U23: 0.2 | V23: 升华时重置 | W23: 自然生成矿物有 5% 概率为 Lv2（价值×2，HP×1.5）。 | X23: =IF(P23="COIN_BONUS",INDEX(Balance!$E$4:$E$9,MIN(6,D23))*T23,IF(P23="MANUAL_REWARD_BONUS",INDEX(Balance!$E$4:$E$9,MIN(6,D23))*Balance!$B$9*T23,IF(P23="GLOBAL_MULTIPLIER",INDEX(Balance!$E$4:$E$9,MIN(6,D23))*(T23-1),""))) | Y23: =IFERROR(L23/X23,"") | Z23: =IF(D23<=2,Balance!$B$10,IF(D23<=4,Balance!$B$11,Balance!$B$12)) | AA23: =IF(X23="","",ROUND(X23*Z23,0)) | AB23: 自然等级抽取必须独立于 upgrade 地块。
A24: ore_giant_vein | B24: 巨型矿脉 | C24: 矿石 | D24: 4 | E24: 4 | F24: -1 | G24: ore_large_vein | H24: 1 | I24: 金币 | J24: 50000 | K24: 1 | L24: =J24 | M24: =IF(H24>=2,ROUND(J24*K24,0),"") | N24: =IF(H24>=3,ROUND(J24*K24^2,0),"") | O24: 大型矿脉 | P24: NATURAL_LEVEL_CHANCE | Q24: ORE | R24: level_3 | S24: SET | T24: 0.05 | U24: 0.1 | V24: 升华时重置 | W24: 自然生成矿物有 5% 概率为 Lv3（价值×4，HP×2.25）。 | X24: =IF(P24="COIN_BONUS",INDEX(Balance!$E$4:$E$9,MIN(6,D24))*T24,IF(P24="MANUAL_REWARD_BONUS",INDEX(Balance!$E$4:$E$9,MIN(6,D24))*Balance!$B$9*T24,IF(P24="GLOBAL_MULTIPLIER",INDEX(Balance!$E$4:$E$9,MIN(6,D24))*(T24-1),""))) | Y24: =IFERROR(L24/X24,"") | Z24: =IF(D24<=2,Balance!$B$10,IF(D24<=4,Balance!$B$11,Balance!$B$12)) | AA24: =IF(X24="","",ROUND(X24*Z24,0)) | AB24: 1%在当前成本下过弱；先判定Lv3，再判定Lv2，概率不要重叠。
A25: ore_rare_focus | B25: 稀有聚焦 | C25: 矿石 | D25: 5 | E25: 5 | F25: -1 | G25: ore_unlock_diamond,ore_giant_vein | H25: 1 | I25: 金币 | J25: 75000 | K25: 1 | L25: =J25 | M25: =IF(H25>=2,ROUND(J25*K25,0),"") | N25: =IF(H25>=3,ROUND(J25*K25^2,0),"") | O25: 钻石钻探与巨型矿脉 | P25: ORE_WEIGHT_BONUS | Q25: ORE | R25: rarity_3_plus | S25: ADD_PERCENT | T25: 0.25 | U25: 1 | V25: 升华时重置 | W25: 稀有度3以上矿物的自然生成权重 +25%。 | X25: =IF(P25="COIN_BONUS",INDEX(Balance!$E$4:$E$9,MIN(6,D25))*T25,IF(P25="MANUAL_REWARD_BONUS",INDEX(Balance!$E$4:$E$9,MIN(6,D25))*Balance!$B$9*T25,IF(P25="GLOBAL_MULTIPLIER",INDEX(Balance!$E$4:$E$9,MIN(6,D25))*(T25-1),""))) | Y25: =IFERROR(L25/X25,"") | Z25: =IF(D25<=2,Balance!$B$10,IF(D25<=4,Balance!$B$11,Balance!$B$12)) | AA25: =IF(X25="","",ROUND(X25*Z25,0)) | AB25: 先过滤已解锁矿，再调整权重；建议总加成上限100%。
A26: tile_unlock_stone | B26: 石质工程 | C26: 地块 | D26: 1 | E26: 0 | F26: 1 | H26: 1 | I26: 金币 | J26: 300 | K26: 1 | L26: =J26 | M26: =IF(H26>=2,ROUND(J26*K26,0),"") | N26: =IF(H26>=3,ROUND(J26*K26^2,0),"") | O26: 初始仅 dirt / grass | P26: UNLOCK_TILE | Q26: TILE | R26: stone | S26: UNLOCK | T26: 1 | U26: 1 | V26: 升华时重置 | W26: 解锁 stone 地块；基础价值倍率 1.5。 | X26: =IF(P26="COIN_BONUS",INDEX(Balance!$E$4:$E$9,MIN(6,D26))*T26,IF(P26="MANUAL_REWARD_BONUS",INDEX(Balance!$E$4:$E$9,MIN(6,D26))*Balance!$B$9*T26,IF(P26="GLOBAL_MULTIPLIER",INDEX(Balance!$E$4:$E$9,MIN(6,D26))*(T26-1),""))) | Y26: =IFERROR(L26/X26,"") | Z26: =IF(D26<=2,Balance!$B$10,IF(D26<=4,Balance!$B$11,Balance!$B$12)) | AA26: =IF(X26="","",ROUND(X26*Z26,0)) | AB26: TileDrawer显示与放置入口都必须校验解锁。
A27: tile_unlock_water | B27: 水域工程 | C27: 地块 | D27: 2 | E27: -1 | F27: 2 | G27: tile_unlock_stone | H27: 1 | I27: 金币 | J27: 500 | K27: 1 | L27: =J27 | M27: =IF(H27>=2,ROUND(J27*K27,0),"") | N27: =IF(H27>=3,ROUND(J27*K27^2,0),"") | O27: 石质工程 | P27: UNLOCK_TILE | Q27: TILE | R27: water | S27: UNLOCK | T27: 1 | U27: 1 | V27: 升华时重置 | W27: 解锁 water 地块；沉没矿物返还10%价值。 | X27: =IF(P27="COIN_BONUS",INDEX(Balance!$E$4:$E$9,MIN(6,D27))*T27,IF(P27="MANUAL_REWARD_BONUS",INDEX(Balance!$E$4:$E$9,MIN(6,D27))*Balance!$B$9*T27,IF(P27="GLOBAL_MULTIPLIER",INDEX(Balance!$E$4:$E$9,MIN(6,D27))*(T27-1),""))) | Y27: =IFERROR(L27/X27,"") | Z27: =IF(D27<=2,Balance!$B$10,IF(D27<=4,Balance!$B$11,Balance!$B$12)) | AA27: =IF(X27="","",ROUND(X27*Z27,0)) | AB27: 返还率0.1目前硬编码，应移入可修改参数。
A28: tile_unlock_fire | B28: 熔岩工程 | C28: 地块 | D28: 2 | E28: 1 | F28: 2 | G28: tile_unlock_stone | H28: 1 | I28: 金币 | J28: 2000 | K28: 1 | L28: =J28 | M28: =IF(H28>=2,ROUND(J28*K28,0),"") | N28: =IF(H28>=3,ROUND(J28*K28^2,0),"") | O28: 石质工程 | P28: UNLOCK_TILE | Q28: TILE | R28: fire | S28: UNLOCK | T28: 1 | U28: 1 | V28: 升华时重置 | W28: 解锁 fire 地块；每1秒对同格矿物造成10伤害。 | X28: =IF(P28="COIN_BONUS",INDEX(Balance!$E$4:$E$9,MIN(6,D28))*T28,IF(P28="MANUAL_REWARD_BONUS",INDEX(Balance!$E$4:$E$9,MIN(6,D28))*Balance!$B$9*T28,IF(P28="GLOBAL_MULTIPLIER",INDEX(Balance!$E$4:$E$9,MIN(6,D28))*(T28-1),""))) | Y28: =IFERROR(L28/X28,"") | Z28: =IF(D28<=2,Balance!$B$10,IF(D28<=4,Balance!$B$11,Balance!$B$12)) | AA28: =IF(X28="","",ROUND(X28*Z28,0)) | AB28: 自动击杀原因标记为 fire。
A29: tile_unlock_pull | B29: 磁吸工程 | C29: 地块 | D29: 3 | E29: -2 | F29: 3 | G29: tile_unlock_water | H29: 1 | I29: 金币 | J29: 5000 | K29: 1 | L29: =J29 | M29: =IF(H29>=2,ROUND(J29*K29,0),"") | N29: =IF(H29>=3,ROUND(J29*K29^2,0),"") | O29: 水域工程 | P29: UNLOCK_TILE | Q29: TILE | R29: pull | S29: UNLOCK | T29: 1 | U29: 1 | V29: 升华时重置 | W29: 解锁 pull 地块；每2秒吸取一个正交邻格矿物。 | X29: =IF(P29="COIN_BONUS",INDEX(Balance!$E$4:$E$9,MIN(6,D29))*T29,IF(P29="MANUAL_REWARD_BONUS",INDEX(Balance!$E$4:$E$9,MIN(6,D29))*Balance!$B$9*T29,IF(P29="GLOBAL_MULTIPLIER",INDEX(Balance!$E$4:$E$9,MIN(6,D29))*(T29-1),""))) | Y29: =IFERROR(L29/X29,"") | Z29: =IF(D29<=2,Balance!$B$10,IF(D29<=4,Balance!$B$11,Balance!$B$12)) | AA29: =IF(X29="","",ROUND(X29*Z29,0)) | AB29: 目标选择保持随机或在文档中另行规定。
A30: tile_unlock_push | B30: 输送工程 | C30: 地块 | D30: 3 | E30: 0 | F30: 3 | G30: tile_unlock_water | H30: 1 | I30: 金币 | J30: 5000 | K30: 1 | L30: =J30 | M30: =IF(H30>=2,ROUND(J30*K30,0),"") | N30: =IF(H30>=3,ROUND(J30*K30^2,0),"") | O30: 水域工程 | P30: UNLOCK_TILE | Q30: TILE | R30: push | S30: UNLOCK | T30: 1 | U30: 1 | V30: 升华时重置 | W30: 解锁 push 地块；每2秒随机推动同格矿物。 | X30: =IF(P30="COIN_BONUS",INDEX(Balance!$E$4:$E$9,MIN(6,D30))*T30,IF(P30="MANUAL_REWARD_BONUS",INDEX(Balance!$E$4:$E$9,MIN(6,D30))*Balance!$B$9*T30,IF(P30="GLOBAL_MULTIPLIER",INDEX(Balance!$E$4:$E$9,MIN(6,D30))*(T30-1),""))) | Y30: =IFERROR(L30/X30,"") | Z30: =IF(D30<=2,Balance!$B$10,IF(D30<=4,Balance!$B$11,Balance!$B$12)) | AA30: =IF(X30="","",ROUND(X30*Z30,0)) | AB30: 推入water的返还仍按water规则。
A31: tile_unlock_volcano | B31: 稳定火山 | C31: 地块 | D31: 3 | E31: 2 | F31: 3 | G31: tile_unlock_fire | H31: 1 | I31: 金币 | J31: 150000 | K31: 1 | L31: =J31 | M31: =IF(H31>=2,ROUND(J31*K31,0),"") | N31: =IF(H31>=3,ROUND(J31*K31^2,0),"") | O31: 熔岩工程 | P31: UNLOCK_TILE | Q31: TILE | R31: volcano_stable | S31: UNLOCK | T31: 1 | U31: 1 | V31: 升华时重置 | W31: 解锁 volcano_stable；每2秒对四个正交邻格造成30伤害。 | X31: =IF(P31="COIN_BONUS",INDEX(Balance!$E$4:$E$9,MIN(6,D31))*T31,IF(P31="MANUAL_REWARD_BONUS",INDEX(Balance!$E$4:$E$9,MIN(6,D31))*Balance!$B$9*T31,IF(P31="GLOBAL_MULTIPLIER",INDEX(Balance!$E$4:$E$9,MIN(6,D31))*(T31-1),""))) | Y31: =IFERROR(L31/X31,"") | Z31: =IF(D31<=2,Balance!$B$10,IF(D31<=4,Balance!$B$11,Balance!$B$12)) | AA31: =IF(X31="","",ROUND(X31*Z31,0)) | AB31: 准确ID为 volcano_stable；自身不能承载矿物。
A32: tile_unlock_spawn | B32: 水晶矿脉 | C32: 地块 | D32: 4 | E32: -2 | F32: 4 | G32: tile_unlock_pull,tile_unlock_push,ore_unlock_crystal | H32: 1 | I32: 金币 | J32: 15000 | K32: 1 | L32: =J32 | M32: =IF(H32>=2,ROUND(J32*K32,0),"") | N32: =IF(H32>=3,ROUND(J32*K32^2,0),"") | O32: 磁吸、输送、水晶勘探 | P32: UNLOCK_TILE | Q32: TILE | R32: spawn | S32: UNLOCK | T32: 1 | U32: 1 | V32: 升华时重置 | W32: 解锁 spawn；空置时每5秒生成一个已解锁的 crystal。 | X32: =IF(P32="COIN_BONUS",INDEX(Balance!$E$4:$E$9,MIN(6,D32))*T32,IF(P32="MANUAL_REWARD_BONUS",INDEX(Balance!$E$4:$E$9,MIN(6,D32))*Balance!$B$9*T32,IF(P32="GLOBAL_MULTIPLIER",INDEX(Balance!$E$4:$E$9,MIN(6,D32))*(T32-1),""))) | Y32: =IFERROR(L32/X32,"") | Z32: =IF(D32<=2,Balance!$B$10,IF(D32<=4,Balance!$B$11,Balance!$B$12)) | AA32: =IF(X32="","",ROUND(X32*Z32,0)) | AB32: 必须校验 crystal；V2建议最多拥有2块，放置基础成本20K。
A33: tile_unlock_upgrade | B33: 升级台 | C33: 地块 | D33: 4 | E33: 0 | F33: 4 | G33: tile_unlock_fire,ore_large_vein | H33: 1 | I33: 金币 | J33: 30000 | K33: 1 | L33: =J33 | M33: =IF(H33>=2,ROUND(J33*K33,0),"") | N33: =IF(H33>=3,ROUND(J33*K33^2,0),"") | O33: 熔岩工程与大型矿脉 | P33: UNLOCK_TILE | Q33: TILE | R33: upgrade | S33: UNLOCK | T33: 1 | U33: 1 | V33: 升华时重置 | W33: 解锁 upgrade；每3秒令同格矿物升1级。 | X33: =IF(P33="COIN_BONUS",INDEX(Balance!$E$4:$E$9,MIN(6,D33))*T33,IF(P33="MANUAL_REWARD_BONUS",INDEX(Balance!$E$4:$E$9,MIN(6,D33))*Balance!$B$9*T33,IF(P33="GLOBAL_MULTIPLIER",INDEX(Balance!$E$4:$E$9,MIN(6,D33))*(T33-1),""))) | Y33: =IFERROR(L33/X33,"") | Z33: =IF(D33<=2,Balance!$B$10,IF(D33<=4,Balance!$B$11,Balance!$B$12)) | AA33: =IF(X33="","",ROUND(X33*Z33,0)) | AB33: 最高等级必须受已解锁自然等级/单独升级上限约束。
A34: tile_fire_rate | B34: 高温燃烧 | C34: 地块 | D34: 4 | E34: 2 | F34: 4 | G34: tile_unlock_fire | H34: 2 | I34: 金币 | J34: 8000 | K34: 5 | L34: =J34 | M34: =IF(H34>=2,ROUND(J34*K34,0),"") | N34: =IF(H34>=3,ROUND(J34*K34^2,0),"") | O34: 熔岩工程 | P34: TILE_RATE_BONUS | Q34: TILE | R34: fire | S34: ADD_PERCENT | T34: 0.15 | U34: 0.3 | V34: 升华时重置 | W34: 每级使 fire 的触发速率 +15%。 | X34: =IF(P34="COIN_BONUS",INDEX(Balance!$E$4:$E$9,MIN(6,D34))*T34,IF(P34="MANUAL_REWARD_BONUS",INDEX(Balance!$E$4:$E$9,MIN(6,D34))*Balance!$B$9*T34,IF(P34="GLOBAL_MULTIPLIER",INDEX(Balance!$E$4:$E$9,MIN(6,D34))*(T34-1),""))) | Y34: =IFERROR(L34/X34,"") | Z34: =IF(D34<=2,Balance!$B$10,IF(D34<=4,Balance!$B$11,Balance!$B$12)) | AA34: =IF(X34="","",ROUND(X34*Z34,0)) | AB34: 按 rate 加成计算：interval=base/(1+rate_bonus)。
A35: tile_water_salvage | B35: 沉底打捞 | C35: 地块 | D35: 5 | E35: -2 | F35: 5 | G35: tile_unlock_water | H35: 2 | I35: 金币 | J35: 8000 | K35: 5 | L35: =J35 | M35: =IF(H35>=2,ROUND(J35*K35,0),"") | N35: =IF(H35>=3,ROUND(J35*K35^2,0),"") | O35: 水域工程 | P35: SINK_REWARD_RATIO | Q35: TILE | R35: water | S35: ADD | T35: 0.05 | U35: 0.2 | V35: 升华时重置 | W35: 每级使 water 的返还比例 +5个百分点，最高20%。 | X35: =IF(P35="COIN_BONUS",INDEX(Balance!$E$4:$E$9,MIN(6,D35))*T35,IF(P35="MANUAL_REWARD_BONUS",INDEX(Balance!$E$4:$E$9,MIN(6,D35))*Balance!$B$9*T35,IF(P35="GLOBAL_MULTIPLIER",INDEX(Balance!$E$4:$E$9,MIN(6,D35))*(T35-1),""))) | Y35: =IFERROR(L35/X35,"") | Z35: =IF(D35<=2,Balance!$B$10,IF(D35<=4,Balance!$B$11,Balance!$B$12)) | AA35: =IF(X35="","",ROUND(X35*Z35,0)) | AB35: 把硬编码0.1迁移到 TileDef/ModifierSet。
A36: tile_unlock_rarity | B36: 稀有矿脉 | C36: 地块 | D36: 5 | E36: 0 | F36: 5 | G36: tile_unlock_spawn,tile_unlock_upgrade | H36: 1 | I36: 金币 | J36: 75000 | K36: 1 | L36: =J36 | M36: =IF(H36>=2,ROUND(J36*K36,0),"") | N36: =IF(H36>=3,ROUND(J36*K36^2,0),"") | O36: 水晶矿脉与升级台 | P36: UNLOCK_TILE | Q36: TILE | R36: rarity | S36: UNLOCK | T36: 1 | U36: 1 | V36: 升华时重置 | W36: 解锁 rarity；自动落矿选中该格时，稀有度3以上矿物权重 +50%。 | X36: =IF(P36="COIN_BONUS",INDEX(Balance!$E$4:$E$9,MIN(6,D36))*T36,IF(P36="MANUAL_REWARD_BONUS",INDEX(Balance!$E$4:$E$9,MIN(6,D36))*Balance!$B$9*T36,IF(P36="GLOBAL_MULTIPLIER",INDEX(Balance!$E$4:$E$9,MIN(6,D36))*(T36-1),""))) | Y36: =IFERROR(L36/X36,"") | Z36: =IF(D36<=2,Balance!$B$10,IF(D36<=4,Balance!$B$11,Balance!$B$12)) | AA36: =IF(X36="","",ROUND(X36*Z36,0)) | AB36: V2不再硬过滤min_rarity=3；建议最多拥有1块，避免高阶矿值导致经济爆炸。
A37: tile_stone_value | B37: 精炼岩床 | C37: 地块 | D37: 5 | E37: 2 | F37: 5 | G37: tile_unlock_stone | H37: 2 | I37: 金币 | J37: 12000 | K37: 5 | L37: =J37 | M37: =IF(H37>=2,ROUND(J37*K37,0),"") | N37: =IF(H37>=3,ROUND(J37*K37^2,0),"") | O37: 石质工程 | P37: TILE_VALUE_MULTIPLIER | Q37: TILE | R37: stone | S37: ADD | T37: 0.15 | U37: 1.8 | V37: 升华时重置 | W37: 每级使 stone 的结算倍率 +0.15，最高1.8。 | X37: =IF(P37="COIN_BONUS",INDEX(Balance!$E$4:$E$9,MIN(6,D37))*T37,IF(P37="MANUAL_REWARD_BONUS",INDEX(Balance!$E$4:$E$9,MIN(6,D37))*Balance!$B$9*T37,IF(P37="GLOBAL_MULTIPLIER",INDEX(Balance!$E$4:$E$9,MIN(6,D37))*(T37-1),""))) | Y37: =IFERROR(L37/X37,"") | Z37: =IF(D37<=2,Balance!$B$10,IF(D37<=4,Balance!$B$11,Balance!$B$12)) | AA37: =IF(X37="","",ROUND(X37*Z37,0)) | AB37: 与岩层鉴价师共享上限，避免重复突破。
A38: tile_grass_damage | B38: 坚韧草根 | C38: 地块 | D38: 6 | E38: -1 | F38: 6 | G38: tile_unlock_stone | H38: 2 | I38: 金币 | J38: 3000 | K38: 5 | L38: =J38 | M38: =IF(H38>=2,ROUND(J38*K38,0),"") | N38: =IF(H38>=3,ROUND(J38*K38^2,0),"") | O38: 石质工程 | P38: TILE_DAMAGE_MULTIPLIER | Q38: TILE | R38: grass | S38: ADD | T38: 0.15 | U38: 1.8 | V38: 升华时重置 | W38: 每级使 grass 上的手动挖矿伤害倍率 +0.15，最高1.8。 | X38: =IF(P38="COIN_BONUS",INDEX(Balance!$E$4:$E$9,MIN(6,D38))*T38,IF(P38="MANUAL_REWARD_BONUS",INDEX(Balance!$E$4:$E$9,MIN(6,D38))*Balance!$B$9*T38,IF(P38="GLOBAL_MULTIPLIER",INDEX(Balance!$E$4:$E$9,MIN(6,D38))*(T38-1),""))) | Y38: =IFERROR(L38/X38,"") | Z38: =IF(D38<=2,Balance!$B$10,IF(D38<=4,Balance!$B$11,Balance!$B$12)) | AA38: =IF(X38="","",ROUND(X38*Z38,0)) | AB38: grass从开局可用，因此这是升级而非解锁。
A39: tile_network | B39: 自动化网络 | C39: 地块 | D39: 6 | E39: 1 | F39: 6 | G39: tile_unlock_rarity,tile_unlock_volcano | H39: 1 | I39: 金币 | J39: 300000 | K39: 1 | L39: =J39 | M39: =IF(H39>=2,ROUND(J39*K39,0),"") | N39: =IF(H39>=3,ROUND(J39*K39^2,0),"") | O39: 稀有矿脉与稳定火山 | P39: TILE_RATE_BONUS | Q39: TILE | R39: periodic_all | S39: ADD_PERCENT | T39: 0.2 | U39: 0.2 | V39: 升华时重置 | W39: 分支终点：所有周期地块触发速率 +20%。 | X39: =IF(P39="COIN_BONUS",INDEX(Balance!$E$4:$E$9,MIN(6,D39))*T39,IF(P39="MANUAL_REWARD_BONUS",INDEX(Balance!$E$4:$E$9,MIN(6,D39))*Balance!$B$9*T39,IF(P39="GLOBAL_MULTIPLIER",INDEX(Balance!$E$4:$E$9,MIN(6,D39))*(T39-1),""))) | Y39: =IFERROR(L39/X39,"") | Z39: =IF(D39<=2,Balance!$B$10,IF(D39<=4,Balance!$B$11,Balance!$B$12)) | AA39: =IF(X39="","",ROUND(X39*Z39,0)) | AB39: 统一rate池；有效间隔不得低于0.25秒。

Sheet Advanced_Talents
A1: Advanced Talents · 升华天赋
A2: 永久树以规则变化、自动化与重开便利为主；消费点数不降低历史点数提供的永久倍率。
A4: Node_ID | B4: 名称 | C4: 层级 | D4: X | E4: Y | F4: 前置_IDs | G4: 升华点成本 | H4: Effect_Type | I4: Target_ID | J4: Operation | K4: 数值 | L4: 永久性 | M4: 玩家描述 | N4: 实现说明
A5: meta_start_cache | B5: 祖传零钱 | C5: 1 | D5: -1 | E5: -1 | G5: 1 | H5: STARTING_COINS | I5: run_start | J5: SET | K5: 100 | L5: 永久 | M5: 新一轮从100金币开始。 | N5: 重置完成后写入统一钱包。
A6: meta_deep_pockets | B6: 深口袋 | C6: 1 | D6: 1 | E6: -1 | G6: 3 | H6: PRESTIGE_COIN_BONUS | I6: all_rewards | J6: ADD_PERCENT | K6: 0.1 | L6: 永久 | M6: 全部金币收益永久 +10%。 | N6: 与每个历史升华点的1%处于同一Prestige层内相加。
A7: meta_permanent_slot_1 | B7: 永久记忆 I | C7: 2 | D7: -2 | E7: -2 | F7: meta_start_cache | G7: 5 | H7: PERMANENT_SLOT | I7: basic_talent | J7: ADD | K7: 1 | L7: 永久 | M7: 升华时可保留一个已购买的Basic天赋。 | N7: 保留槽应保存天赋ID；不可保留升华动作。
A8: meta_auto_pick | B8: 自动镐 | C8: 2 | D8: 0 | E8: -2 | F8: meta_start_cache,meta_deep_pockets | G8: 10 | H8: AUTO_PICK | I8: random_ore | J8: SET | K8: 2 | L8: 永久 | M8: 每2秒自动攻击一个矿物。 | N8: 击杀原因标记为auto_pick，不享受手工精品。
A9: meta_offline | B9: 离线远征 | C9: 2 | D9: 2 | E9: -2 | F9: meta_deep_pockets | G9: 15 | H9: OFFLINE_INCOME | I9: offline | J9: SET | K9: 0.1 | L9: 永久 | M9: 获得10%离线收益，最多累计2小时。 | N9: 用保存时间差结算；必须限制最大离线时长。
A10: meta_geology_synergy | B10: 地质协同 | C10: 3 | D10: -2 | E10: -3 | F10: meta_permanent_slot_1 | G10: 25 | H10: UNLOCK_SYNERGY | I10: ore_tile | J10: UNLOCK | K10: 1 | L10: 永久 | M10: 解锁矿石与地块的非对称协同。 | N10: 每条协同建议封顶2~3倍，避免9格网格爆炸。
A11: meta_golden_vein | B11: 黄金矿脉事件 | C11: 3 | D11: 0 | E11: -3 | F11: meta_auto_pick,meta_offline | G11: 50 | H11: UNLOCK_EVENT | I11: golden_vein | J11: UNLOCK | K11: 1 | L11: 永久 | M11: 偶尔出现限时高收益矿脉。 | N11: 奖励取 min(银行比例, 当前CPS×固定秒数)。
A12: meta_permanent_slot_2 | B12: 永久记忆 II | C12: 4 | D12: -1 | E12: -4 | F12: meta_geology_synergy,meta_golden_vein | G12: 100 | H12: PERMANENT_SLOT | I12: basic_talent | J12: ADD | K12: 1 | L12: 永久 | M12: 额外增加一个Basic永久保留槽。 | N12: 总永久槽建议保持稀少。
A13: meta_automation_network | B13: 永续自动化 | C13: 4 | D13: 1 | E13: -4 | F13: meta_golden_vein | G13: 250 | H13: OFFLINE_RATE_BONUS | I13: offline | J13: ADD_PERCENT | K13: 0.15 | L13: 永久 | M13: 离线收益率再 +15%，离线上限延长至8小时。 | N13: 与离线远征同层相加；最终离线率建议不超过50%。

Sheet Tree_View
A1: 天赋树视觉稿
A2: 点击节点可跳转到权威数据行。连线仅作阅读辅助；多个前置以数据表中的前置_IDs为准。
A4: Basic · 本轮天赋
B5: -5 | D5: -4 | F5: -3 | H5: -2 | J5: -1 | L5: 0 | N5: 1 | P5: 2 | R5: 3 | T5: 4 | V5: 5
A6: -5 | J6: 余震 25,000 | N6: 冲击波 150,000
J7: │ | N7: │
A8: -4 | J8: 精准爆破 5,000 | N8: 双重敲击 8,000
J9: │ | N9: │
A10: -3 | J10: ─ | K10: ─ | L10: 幸运重击 1,000 | M10: ─ | N10: ─
L11: │
A12: -2 | L12: 锐利镐刃 250
L13: │
A14: -1 | B14: ─ | C14: ─ | D14: 岩层鉴价师 5,000 | L14: 淬火镐头 50 | M14: ─ | N14: ─ | O14: ─ | P14: ─ | Q14: ─ | R14: 大型矿脉 5,000 | S14: ─ | T14: 巨型矿脉 50,000 | U14: ─ | V14: 稀有聚焦 75,000
B15: │ | D15: │ | L15: │ | R15: │ | V15: │
A16: 0 | B16: 黄金比例 300,000 | D16: ─ | E16: ─ | F16: 连续开采 500 | G16: ─ | H16: 手工精品 25 | I16: ─ | J16: 矿物鉴价 10 | K16: ─ | L16: 重置·升华 ACTION | M16: ─ | N16: 发现黄金 250 | O16: ─ | P16: 水晶勘探 2,500 | Q16: ─ | R16: 黑曜层 12,000 | S16: ─ | T16: 钻石钻探 30,000 | U16: ─ | V16: 猫矿传说 250,000
B17: │ | D17: │ | H17: │ | L17: │
A18: 1 | B18: ─ | C18: ─ | D18: 纪录狂热 50,000 | H18: │ | J18: ─ | K18: ─ | L18: 石质工程 300 | M18: ─ | N18: ─ | O18: ─ | P18: ─
H19: │ | J19: │ | L19: │ | N19: │ | P19: │
A20: 2 | H20: ─ | I20: ─ | J20: 水域工程 500 | K20: ─ | L20: ─ | M20: ─ | N20: 熔岩工程 2,000 | O20: ─ | P20: ─
H21: │ | J21: │ | L21: │ | P21: │
A22: 3 | H22: 磁吸工程 5,000 | I22: ─ | J22: ─ | K22: ─ | L22: 输送工程 5,000 | N22: ─ | O22: ─ | P22: 稳定火山 150,000
H23: │ | J23: │ | L23: │ | N23: │ | P23: │
A24: 4 | H24: 水晶矿脉 15,000 | I24: ─ | J24: ─ | K24: ─ | L24: 升级台 30,000 | N24: │ | P24: 高温燃烧 8,000
H25: │ | J25: │ | L25: │ | N25: │ | P25: │
A26: 5 | H26: 沉底打捞 8,000 | J26: │ | L26: 稀有矿脉 75,000 | M26: ─ | N26: ─ | P26: 精炼岩床 12,000
J27: │ | N27: │
A28: 6 | J28: 坚韧草根 3,000 | N28: 自动化网络 300,000
A32: Advanced · 永久天赋
B33: -2 | D33: -1 | F33: 0 | H33: 1 | J33: 2
A34: -4 | D34: 永久记忆 II 100 | H34: 永续自动化 250
D35: │ | H35: │
A36: -3 | B36: 地质协同 25 | C36: ─ | D36: ─ | E36: ─ | F36: 黄金矿脉事件 50 | G36: ─ | H36: ─
B37: │ | F37: │
A38: -2 | B38: 永久记忆 I 5 | F38: 自动镐 10 | G38: ─ | H38: ─ | I38: ─ | J38: 离线远征 15
B39: │ | F39: │ | J39: │
A40: -1 | B40: ─ | C40: ─ | D40: 祖传零钱 1 | E40: ─ | F40: ─ | G40: ─ | H40: 深口袋 3 | I40: ─ | J40: ─
D41: │ | H41: │
A42: 0 | D42: ─ | E42: ─ | F42: 重置·升华 ACTION | G42: ─ | H42: ─
A55: 图例 | B55: 镐子 | C55: 金币 | D55: 矿石 | E55: 地块 | F55: 升华

Sheet Balance
A1: Balance Lab · 数值与回本
A2: 黄色单元格为输入；蓝色单元格为公式。Excel/WPS打开时自动重算。
A3: 参数 | B3: 值 | C3: 说明 | D3: Tier | E3: 该阶段假设CPS | F3: 用途 | G3: 金币里程碑耗时
A4: 自动落矿间隔（秒） | B4: 2 | C4: 当前GameManager默认每2秒尝试落1矿。 | D4: 1 | E4: =$B$7 | F4: Basic表简单百分比天赋的ROI估算；应被实机遥测替换。 | G4: 里程碑 | H4: V2初始理论秒 | I4: 当前全池理论秒 | J4: V2初始可读时间
A5: V2初始矿池期望价值/次 | B5: =SUMPRODUCT((Content_Catalog!$A$5:$A$12="ORE")*(Content_Catalog!$I$5:$I$12="是")*Content_Catalog!$N$5:$N$12*Content_Catalog!$F$5:$F$12)/SUMPRODUCT((Content_Catalog!$A$5:$A$12="ORE")*(Content_Catalog!$I$5:$I$12="是")*Content_Catalog!$F$5:$F$12) | C5: coal/iron/zinc按V2建议价值与生成权重加权。 | D5: 2 | E5: 2 | F5: Basic表简单百分比天赋的ROI估算；应被实机遥测替换。 | G5: 100 | H5: =G5/$B$7 | I5: =G5/$B$8 | J5: =IF(H5<60,TEXT(H5,"0.0")&"秒",IF(H5<3600,TEXT(H5/60,"0.0")&"分钟",IF(H5<86400,TEXT(H5/3600,"0.0")&"小时",TEXT(H5/31557600,"0.00")&"年")))
A6: 当前全部矿池期望价值/次 | B6: =SUMPRODUCT(Content_Catalog!$E$5:$E$12,Content_Catalog!$F$5:$F$12)/SUM(Content_Catalog!$F$5:$F$12) | C6: 仓库当前全部8矿从开局进入随机池。 | D6: 3 | E6: 6 | F6: Basic表简单百分比天赋的ROI估算；应被实机遥测替换。 | G6: 1000 | H6: =G6/$B$7 | I6: =G6/$B$8 | J6: =IF(H6<60,TEXT(H6,"0.0")&"秒",IF(H6<3600,TEXT(H6/60,"0.0")&"分钟",IF(H6<86400,TEXT(H6/3600,"0.0")&"小时",TEXT(H6/31557600,"0.00")&"年")))
A7: V2初始理论最大CPS | B7: =B5/B4 | C7: 假设矿物立即清除；实际值会更低。 | D7: 4 | E7: 26 | F7: Basic表简单百分比天赋的ROI估算；应被实机遥测替换。 | G7: 10000 | H7: =G7/$B$7 | I7: =G7/$B$8 | J7: =IF(H7<60,TEXT(H7,"0.0")&"秒",IF(H7<3600,TEXT(H7/60,"0.0")&"分钟",IF(H7<86400,TEXT(H7/3600,"0.0")&"小时",TEXT(H7/31557600,"0.00")&"年")))
A8: 当前全部矿理论最大CPS | B8: =B6/B4 | C8: 用于对照旧设计。 | D8: 5 | E8: 500 | F8: Basic表简单百分比天赋的ROI估算；应被实机遥测替换。 | G8: 100000 | H8: =G8/$B$7 | I8: =G8/$B$8 | J8: =IF(H8<60,TEXT(H8,"0.0")&"秒",IF(H8<3600,TEXT(H8/60,"0.0")&"分钟",IF(H8<86400,TEXT(H8/3600,"0.0")&"小时",TEXT(H8/31557600,"0.00")&"年")))
A9: 手动击杀收益占比 | B9: 0.7 | C9: 用于估算手工精品；需用遥测替换。 | D9: 6 | E9: 1000 | F9: Basic表简单百分比天赋的ROI估算；应被实机遥测替换。 | G9: 1000000 | H9: =G9/$B$7 | I9: =G9/$B$8 | J9: =IF(H9<60,TEXT(H9,"0.0")&"秒",IF(H9<3600,TEXT(H9/60,"0.0")&"分钟",IF(H9<86400,TEXT(H9/3600,"0.0")&"小时",TEXT(H9/31557600,"0.00")&"年")))
A10: 早期目标回本秒 | B10: 90 | C10: Tier 1~2。 | G10: 1000000000 | H10: =G10/$B$7 | I10: =G10/$B$8 | J10: =IF(H10<60,TEXT(H10,"0.0")&"秒",IF(H10<3600,TEXT(H10/60,"0.0")&"分钟",IF(H10<86400,TEXT(H10/3600,"0.0")&"小时",TEXT(H10/31557600,"0.00")&"年")))
A11: 中期目标回本秒 | B11: 300 | C11: Tier 3~4。
A12: 里程碑目标回本秒 | B12: 600 | C12: Tier 5以上；内容解锁可不使用直接ROI。 | G12: 升华公式样例
A13: 首次升华门槛 C | B13: 1000000 | C13: 偏长线版本；30~60分钟首轮可改为100000。 | G13: L/C | H13: 终身金币 | I13: 计算点数 | J13: 期望点数 | K13: 通过 | L13: 永久倍率
A14: 终身金币 L（测试输入） | B14: 1000000 | C14: 修改以测试升华收益。 | G14: 0.999999 | H14: =G14*$B$13 | I14: =IF(H14<$B$13,0,INT(ROUND(10*POWER(H14/$B$13,1/3),9))) | J14: 0 | K14: =IF(I14=J14,"PASS","CHECK") | L14: =1+I14*1%
A15: 历史已获得升华点 | B15: 0 | C15: 注意不是当前未消费点。 | G15: 1 | H15: =G15*$B$13 | I15: =IF(H15<$B$13,0,INT(ROUND(10*POWER(H15/$B$13,1/3),9))) | J15: 10 | K15: =IF(I15=J15,"PASS","CHECK") | L15: =1+I15*1%
A16: 总升华点 | B16: =IF(B14<B13,0,INT(ROUND(10*POWER(B14/B13,1/3),9))) | C16: L<C时0；否则floor(10×立方根(L/C))；ROUND保护立方边界。 | G16: 1.330999 | H16: =G16*$B$13 | I16: =IF(H16<$B$13,0,INT(ROUND(10*POWER(H16/$B$13,1/3),9))) | J16: 10 | K16: =IF(I16=J16,"PASS","CHECK") | L16: =1+I16*1%
A17: 本次可获得升华点 | B17: =MAX(0,B16-B15) | C17: 总点数减历史已获得点数。 | G17: 1.331 | H17: =G17*$B$13 | I17: =IF(H17<$B$13,0,INT(ROUND(10*POWER(H17/$B$13,1/3),9))) | J17: 11 | K17: =IF(I17=J17,"PASS","CHECK") | L17: =1+I17*1%
A18: 基础Prestige倍率 | B18: =1+B16*1% | C18: 消费点数不降低该倍率。 | G18: 1.727999 | H18: =G18*$B$13 | I18: =IF(H18<$B$13,0,INT(ROUND(10*POWER(H18/$B$13,1/3),9))) | J18: 11 | K18: =IF(I18=J18,"PASS","CHECK") | L18: =1+I18*1%
G19: 1.728 | H19: =G19*$B$13 | I19: =IF(H19<$B$13,0,INT(ROUND(10*POWER(H19/$B$13,1/3),9))) | J19: 12 | K19: =IF(I19=J19,"PASS","CHECK") | L19: =1+I19*1%
G20: 8 | H20: =G20*$B$13 | I20: =IF(H20<$B$13,0,INT(ROUND(10*POWER(H20/$B$13,1/3),9))) | J20: 20 | K20: =IF(I20=J20,"PASS","CHECK") | L20: =1+I20*1%
G21: 125 | H21: =G21*$B$13 | I21: =IF(H21<$B$13,0,INT(ROUND(10*POWER(H21/$B$13,1/3),9))) | J21: 50 | K21: =IF(I21=J21,"PASS","CHECK") | L21: =1+I21*1%
A22: 重复地块成本曲线（Cookie Clicker式1.15增长） | G22: 1000 | H22: =G22*$B$13 | I22: =IF(H22<$B$13,0,INT(ROUND(10*POWER(H22/$B$13,1/3),9))) | J22: 100 | K22: =IF(I22=J22,"PASS","CHECK") | L22: =1+I22*1%
A23: 放置基础成本 | B23: 25
A25: 已拥有数量 | B25: 下一件价格 | C25: 累计购买成本 | D25: 约为基础价倍数 | E25: 备注 | G25: 矿物解锁路径 · 实际回本
A26: 0 | B26: =ROUNDUP($B$23*POWER(1.15,A26),0) | C26: =B26 | D26: =B26/$B$23 | G26: 阶段 | H26: 新增矿物 | I26: 解锁成本 | J26: 当前累计CPS | K26: 当前ΔCPS | L26: 当前回本秒 | M26: V2累计CPS | N26: V2 ΔCPS | O26: V2回本秒
A27: 1 | B27: =ROUNDUP($B$23*POWER(1.15,A27),0) | C27: =IF(A27=0,B27,C26+B27) | D27: =B27/$B$23 | G27: 0 | H27: 初始coal/iron/zinc | I27: 0 | J27: =SUMPRODUCT(Content_Catalog!$E$5:$E$7,Content_Catalog!$F$5:$F$7)/SUM(Content_Catalog!$F$5:$F$7)/$B$4 | M27: =SUMPRODUCT(Content_Catalog!$N$5:$N$7,Content_Catalog!$F$5:$F$7)/SUM(Content_Catalog!$F$5:$F$7)/$B$4
A28: 2 | B28: =ROUNDUP($B$23*POWER(1.15,A28),0) | C28: =IF(A28=0,B28,C27+B28) | D28: =B28/$B$23 | G28: 1 | H28: gold | I28: 250 | J28: =SUMPRODUCT(Content_Catalog!$E$5:$E$8,Content_Catalog!$F$5:$F$8)/SUM(Content_Catalog!$F$5:$F$8)/$B$4 | K28: =J28-J27 | L28: =IF(K28<=0,"",I28/K28) | M28: =SUMPRODUCT(Content_Catalog!$N$5:$N$8,Content_Catalog!$F$5:$F$8)/SUM(Content_Catalog!$F$5:$F$8)/$B$4 | N28: =M28-M27 | O28: =IF(N28<=0,"",I28/N28)
A29: 3 | B29: =ROUNDUP($B$23*POWER(1.15,A29),0) | C29: =IF(A29=0,B29,C28+B29) | D29: =B29/$B$23 | G29: 2 | H29: crystal | I29: 2500 | J29: =SUMPRODUCT(Content_Catalog!$E$5:$E$9,Content_Catalog!$F$5:$F$9)/SUM(Content_Catalog!$F$5:$F$9)/$B$4 | K29: =J29-J28 | L29: =IF(K29<=0,"",I29/K29) | M29: =SUMPRODUCT(Content_Catalog!$N$5:$N$9,Content_Catalog!$F$5:$F$9)/SUM(Content_Catalog!$F$5:$F$9)/$B$4 | N29: =M29-M28 | O29: =IF(N29<=0,"",I29/N29)
A30: 4 | B30: =ROUNDUP($B$23*POWER(1.15,A30),0) | C30: =IF(A30=0,B30,C29+B30) | D30: =B30/$B$23 | G30: 3 | H30: obsidian | I30: 12000 | J30: =SUMPRODUCT(Content_Catalog!$E$5:$E$10,Content_Catalog!$F$5:$F$10)/SUM(Content_Catalog!$F$5:$F$10)/$B$4 | K30: =J30-J29 | L30: =IF(K30<=0,"",I30/K30) | M30: =SUMPRODUCT(Content_Catalog!$N$5:$N$10,Content_Catalog!$F$5:$F$10)/SUM(Content_Catalog!$F$5:$F$10)/$B$4 | N30: =M30-M29 | O30: =IF(N30<=0,"",I30/N30)
A31: 5 | B31: =ROUNDUP($B$23*POWER(1.15,A31),0) | C31: =IF(A31=0,B31,C30+B31) | D31: =B31/$B$23 | E31: 约每5个翻倍 | G31: 4 | H31: diamond | I31: 30000 | J31: =SUMPRODUCT(Content_Catalog!$E$5:$E$11,Content_Catalog!$F$5:$F$11)/SUM(Content_Catalog!$F$5:$F$11)/$B$4 | K31: =J31-J30 | L31: =IF(K31<=0,"",I31/K31) | M31: =SUMPRODUCT(Content_Catalog!$N$5:$N$11,Content_Catalog!$F$5:$F$11)/SUM(Content_Catalog!$F$5:$F$11)/$B$4 | N31: =M31-M30 | O31: =IF(N31<=0,"",I31/N31)
A32: 6 | B32: =ROUNDUP($B$23*POWER(1.15,A32),0) | C32: =IF(A32=0,B32,C31+B32) | D32: =B32/$B$23 | G32: 5 | H32: cat | I32: 250000 | J32: =SUMPRODUCT(Content_Catalog!$E$5:$E$12,Content_Catalog!$F$5:$F$12)/SUM(Content_Catalog!$F$5:$F$12)/$B$4 | K32: =J32-J31 | L32: =IF(K32<=0,"",I32/K32) | M32: =SUMPRODUCT(Content_Catalog!$N$5:$N$12,Content_Catalog!$F$5:$F$12)/SUM(Content_Catalog!$F$5:$F$12)/$B$4 | N32: =M32-M31 | O32: =IF(N32<=0,"",I32/N32)
A33: 7 | B33: =ROUNDUP($B$23*POWER(1.15,A33),0) | C33: =IF(A33=0,B33,C32+B33) | D33: =B33/$B$23
A34: 8 | B34: =ROUNDUP($B$23*POWER(1.15,A34),0) | C34: =IF(A34=0,B34,C33+B34) | D34: =B34/$B$23
A35: 9 | B35: =ROUNDUP($B$23*POWER(1.15,A35),0) | C35: =IF(A35=0,B35,C34+B35) | D35: =B35/$B$23
A36: 10 | B36: =ROUNDUP($B$23*POWER(1.15,A36),0) | C36: =IF(A36=0,B36,C35+B36) | D36: =B36/$B$23 | E36: 约每5个翻倍
A37: 11 | B37: =ROUNDUP($B$23*POWER(1.15,A37),0) | C37: =IF(A37=0,B37,C36+B37) | D37: =B37/$B$23
A38: 12 | B38: =ROUNDUP($B$23*POWER(1.15,A38),0) | C38: =IF(A38=0,B38,C37+B38) | D38: =B38/$B$23
A39: 13 | B39: =ROUNDUP($B$23*POWER(1.15,A39),0) | C39: =IF(A39=0,B39,C38+B39) | D39: =B39/$B$23
A40: 14 | B40: =ROUNDUP($B$23*POWER(1.15,A40),0) | C40: =IF(A40=0,B40,C39+B40) | D40: =B40/$B$23
A41: 15 | B41: =ROUNDUP($B$23*POWER(1.15,A41),0) | C41: =IF(A41=0,B41,C40+B41) | D41: =B41/$B$23 | E41: 约每5个翻倍
...

Sheet Content_Catalog
A1: Content Catalog · 实际ID对照
A2: ‘当前代码开局可用’记录仓库现状；‘V2建议开局可用’记录目标设计，两列不可混用。
A4: 类型 | B4: ID | C4: 名称 | D4: 稀有度/行为 | E4: 基础价值/价值倍率 | F4: 生成权重/触发间隔 | G4: 基础HP/伤害 | H4: 当前代码开局可用 | I4: V2建议开局可用 | J4: 解锁天赋 | K4: 建议放置基础成本 | L4: 资源路径 | M4: 说明 | N4: V2建议基础价值/倍率 | O4: V2数值说明
A5: ORE | B5: coal | C5: 煤矿 | D5: 1 | E5: 2 | F5: 50 | G5: 10 | H5: 是 | I5: 是 | L5: res://defs/ores/coal.tres | M5: Lv1/2/3价值倍率1/2/4，HP倍率1/1.5/2.25。 | N5: 2 | O5: 与当前数值相同；后续用实机数据校准。
A6: ORE | B6: iron | C6: 铁矿 | D6: 1 | E6: 2 | F6: 100 | G6: 10 | H6: 是 | I6: 是 | L6: res://defs/ores/iron.tres | M6: OreDef默认rarity=1、base_hp=10。 | N6: 2 | O6: 与当前数值相同；后续用实机数据校准。
A7: ORE | B7: zinc | C7: 锌矿 | D7: 1 | E7: 3 | F7: 40 | G7: 12 | H7: 是 | I7: 是 | L7: res://defs/ores/zinc.tres | M7: V2初始常见矿。 | N7: 3 | O7: 与当前数值相同；后续用实机数据校准。
A8: ORE | B8: gold | C8: 金矿 | D8: 2 | E8: 12 | F8: 25 | G8: 40 | H8: 是 | I8: 否 | J8: ore_unlock_gold | L8: res://defs/ores/gold.tres | M8: 当前开局强制生成1个gold；实施V2时需移除绕过。 | N8: 12 | O8: 与当前数值相同；后续用实机数据校准。
A9: ORE | B9: crystal | C9: 水晶矿 | D9: 3 | E9: 25 | F9: 10 | G9: 70 | H9: 是 | I9: 否 | J9: ore_unlock_crystal | L9: res://defs/ores/crystal.tres | M9: spawn地块固定生成它，必须执行解锁校验。 | N9: 200 | O9: 价值提升到200，使2.5K解锁在上一阶段约9.5分钟回本。
A10: ORE | B10: obsidian | C10: 黑曜石 | D10: 3 | E10: 35 | F10: 8 | G10: 100 | H10: 是 | I10: 否 | J10: ore_unlock_obsidian | L10: res://defs/ores/obsidian.tres | N10: 1200 | O10: 价值提升到1.2K，使12K解锁约9.8分钟回本。
A11: ORE | B11: diamond | C11: 钻石矿 | D11: 3 | E11: 40 | F11: 5 | G11: 120 | H11: 是 | I11: 否 | J11: ore_unlock_diamond | L11: res://defs/ores/diamond.tres | N11: 5000 | O11: 价值提升到5K，使30K解锁约9.6分钟回本。
A12: ORE | B12: cat | C12: 猫矿 | D12: 4 | E12: 500 | F12: 1 | G12: 300 | H12: 是 | I12: 否 | J12: ore_unlock_cat | L12: res://defs/ores/cat.tres | M12: 不存在emerald；不要恢复旧表中的绿宝石节点。 | N12: 200000 | O12: 价值提升到200K，使250K解锁约10分钟回本；保留weight=1。
A13: TILE | B13: dirt | C13: 泥土 | D13: NONE | E13: 1 | F13: 0 | G13: 0 | H13: 是 | I13: 是 | K13: 0 | L13: res://defs/tiles/dirt.tres | M13: 无效果；V2默认可用。 | N13: 1 | O13: 与当前数值相同；后续用实机数据校准。
A14: TILE | B14: grass | C14: 草地 | D14: GRASS | E14: 1 | F14: 0 | G14: 0 | H14: 是 | I14: 是 | K14: 0 | L14: res://defs/tiles/grass.tres | M14: 手动挖矿伤害倍率1.5；初始3×3均为grass。 | N14: 1 | O14: 与当前数值相同；后续用实机数据校准。
A15: TILE | B15: stone | C15: 石头 | D15: STONE | E15: 1.5 | F15: 0 | G15: 0 | H15: 是 | I15: 否 | J15: tile_unlock_stone | K15: 50 | L15: res://defs/tiles/stone.tres | M15: 旧表rock已改为准确ID stone。 | N15: 1.5 | O15: 与当前数值相同；后续用实机数据校准。
A16: TILE | B16: water | C16: 水域 | D16: WATER | E16: 1 | F16: 0 | G16: 0 | H16: 是 | I16: 否 | J16: tile_unlock_water | K16: 100 | L16: res://defs/tiles/water.tres | M16: 沉没返还10%当前硬编码。 | N16: 1 | O16: 与当前数值相同；后续用实机数据校准。
A17: TILE | B17: fire | C17: 熔岩 | D17: FIRE | E17: 1 | F17: 1 | G17: 10 | H17: 是 | I17: 否 | J17: tile_unlock_fire | K17: 500 | L17: res://defs/tiles/fire.tres | M17: 每1秒对同格矿物造成10伤害。 | N17: 1 | O17: 与当前数值相同；后续用实机数据校准。
A18: TILE | B18: pull | C18: 磁吸 | D18: PULL | E18: 1 | F18: 2 | G18: 0 | H18: 是 | I18: 否 | J18: tile_unlock_pull | K18: 1000 | L18: res://defs/tiles/pull.tres | M18: 每2秒随机吸一个正交邻矿。 | N18: 1 | O18: 与当前数值相同；后续用实机数据校准。
A19: TILE | B19: push | C19: 传送带 | D19: PUSH | E19: 1 | F19: 2 | G19: 0 | H19: 是 | I19: 否 | J19: tile_unlock_push | K19: 1000 | L19: res://defs/tiles/push.tres | M19: 每2秒随机推动同格矿物。 | N19: 1 | O19: 与当前数值相同；后续用实机数据校准。
A20: TILE | B20: spawn | C20: 水晶矿脉 | D20: SPAWN | E20: 1 | F20: 5 | G20: 0 | H20: 是 | I20: 否 | J20: tile_unlock_spawn | K20: 20000 | L20: res://defs/tiles/spawn.tres | M20: 每5秒固定生成crystal，受矿物上限约束。 | N20: 1 | O20: crystal=200时单块理论40 CPS；建议max_owned=2、放置基础成本20K。
A21: TILE | B21: upgrade | C21: 升级台 | D21: UPGRADE | E21: 1 | F21: 3 | G21: 0 | H21: 是 | I21: 否 | J21: tile_unlock_upgrade | K21: 10000 | L21: res://defs/tiles/upgrade.tres | M21: 每3秒使同格矿物+1级，当前最高3。 | N21: 1 | O21: 升级上限必须服从Lv2/Lv3天赋。
A22: TILE | B22: rarity | C22: 稀有矿脉 | D22: RARITY | E22: 1 | F22: 0 | G22: 0 | H22: 是 | I22: 否 | J22: tile_unlock_rarity | K22: 50000 | L22: res://defs/tiles/rarity.tres | M22: 当前仅在自动落矿选中该格时把最低稀有度设为3。 | N22: 1 | O22: 改为rarity≥3权重+50%，不要继续使用min_rarity=3硬过滤；建议max_owned=1。
A23: TILE | B23: volcano_stable | C23: 稳定火山 | D23: VOLCANO | E23: 1 | F23: 2 | G23: 30 | H23: 是 | I23: 否 | J23: tile_unlock_volcano | K23: 30000 | L23: res://defs/tiles/volcano_stable.tres | M23: 旧表volcano已改为准确ID volcano_stable。 | N23: 1 | O23: 与当前数值相同；后续用实机数据校准。

Sheet Change_Log
A1: Change Log · V1 → V2
A2: 记录设计决策、项目差异与需要程序配合的事项。
A4: 优先级 | B4: 类别 | C4: 变更 | D4: 原因 | E4: 代码影响 | F4: 验收条件
A5: P0 | B5: 经济 | C5: 删除每圈成本×1000，改为ROI定价；重复放置才用1.15增长。 | D5: 旧曲线在当前产率下不可达。 | E5: Talent/Tile购买系统 | F5: 模拟表中主要购买的回本时间处于目标区间。
A6: P0 | B6: 钱包 | C6: Basic购买连接GameManager/PlayerProgression权威金币。 | D6: 当前TalentGrid有独立starting_gold。 | E6: 重构TalentGrid购买入口 | F6: HUD与天赋购买显示同一余额并可存档。
A7: P0 | B7: 解锁 | C7: 增加矿物/地块解锁过滤。 | D7: 当前全部内容开局可用。 | E7: DefDb、TileDrawer、放置入口 | F7: 锁定内容不生成、不显示或不可放置。
A8: P0 | B8: 奖励 | C8: ore_removed携带击杀cause。 | D8: 手挖收益、连击和自动化无法区分。 | E8: GridModel、GameManager | F8: manual/fire/volcano/water/auto_pick分别结算。
A9: P1 | B9: 数据 | C9: TalentDef增加等级、多前置、效果数组、上限和描述。 | D9: 当前只有UI数据。 | E9: TalentDef、存档 | F9: Excel字段可一一映射到运行时数据。
A10: P1 | B10: ID | C10: 移除emerald；rock→stone；volcano→volcano_stable。 | D10: 旧表与资源不一致。 | E10: 演示定义与内容清单 | F10: 启动校验无缺失target_id。
A11: P1 | B11: 等级 | C11: 高级/巨大改为全局自然等级概率。 | D11: 逐矿重复节点臃肿，upgrade会绕过。 | E11: spawn_ore、upgrade行为 | F11: Lv2/Lv3生成与升级均服从已解锁上限。
A12: P1 | B12: 矿值 | C12: 增加V2矿值阶梯：12/200/1.2K/5K/200K。 | D12: 保留旧矿值会让后四档解锁回本1.4~67小时。 | E12: OreDef数值（尚未修改） | F12: 按顺序解锁的理论回本约439~598秒。
A13: P1 | B13: 地块 | C13: spawn最多2块；rarity最多1块且改为权重加成。 | D13: 指数矿值会放大固定生成和稀有硬过滤。 | E13: TileDef、放置上限与价格 | F13: 不能用9个spawn/rarity在几十秒内击穿经济。
A14: P1 | B14: 升华 | C14: 重置作为Action；总点数与未消费点分开。 | D14: 消费点不应降低永久倍率。 | E14: PlayerProgression、UI | F14: 预览点数准确，重置后永久数据保留。
A15: P2 | B15: 数值 | C15: 统一同类加法、跨层乘法和效果上限。 | D15: 避免多乘区指数失控。 | E15: ModifierSet | F15: 同一结算顺序有单元测试。
A16: P2 | B16: 展示 | C16: Tree_View只展示，Basic/Advanced为权威表。 | D16: 空间表无法表达公式和依赖。 | E16: 数据导入工具（可选） | F16: 节点点击可回到对应数据行。

Sheet Lists
A1: 镐子 | B1: 金币 | C1: ADD | D1: GLOBAL | E1: 升华时重置 | F1: 是
A2: 金币 | B2: 升华点 | C2: ADD_PERCENT | D2: PICKAXE | E2: 永久 | F2: 否
A3: 矿石 | C3: MULTIPLY | D3: ORE
A4: 地块 | C4: SET | D4: TILE
A5: 升华 | C5: UNLOCK | D5: SYSTEM
